Workbook

Sheet Simple
B2: Simple migration model
B3: Yellow cells are editable. Prefilled numbers are examples, not benchmarks.
B4: Screening result
B5: Next step | C5: =C28 -> Evaluate online | F5: A screening result does not prove online or rollback feasibility.
B6: Required bulk speed | C6: =C24 -> 71.428571 | D6: GB/minute
B7: Estimated offline interruption | C7: =C26 -> 137.5 | D7: Minutes
B8: Rollback | C8: Not assessed | F8: The Simple model cannot confirm recovery within the rollback budget.
B10: Enter the business requirements
B12: Preferred approach | C12: No preference | D12: Choice | F12: Preference does not override requirements.
B13: Data to copy | C13: 1000 | D13: GB | F13: 1 GB = 1 billion bytes. Count data being copied, not empty storage.
B14: Maximum cutover interruption | C14: 30 | D14: Minutes | F14: From stopping source writes until the target application is available.
B15: Maximum rollback interruption | C15: 15 | D15: Minutes | F15: From starting rollback until the source application is available.
B16: Network round-trip delay | C16: 40 | D16: Milliseconds | F16: Used as a test condition. It does not determine transfer speed.
B17: Enter planning assumptions
B18: Other cutover work | C18: 10 | D18: Minutes | F18: Stopping writes, checking readiness and switching connections.
B19: Planning factor | C19: 1.25 | D19: Multiplier | F19: 1.25 adds 25% to the entire estimated interruption.
B20: Assumed bulk speed | C20: 10 | D20: GB/minute | F20: Complete source reading, transfer and target loading rate.
F21: Example assumptions come from the accompanying OraMatt draft.
B22: Follow the calculation
B23: Time available for the copy | C23: =IF(AND(AND(ISNUMBER(C14),C14>0),AND(ISNUMBER(C18),C18>=0),AND(ISNUMBER(C19),C19>=1)),C14/C19-C18,"Unknown") -> 14 | D23: Minutes | F23: Cutover budget / planning factor - other cutover work.
B24: Required bulk speed | C24: =IF(AND(ISNUMBER(C23),C23>0,AND(ISNUMBER(C13),C13>0)),C13/C23,"Unknown") -> 71.428571 | D24: GB/minute | F24: Data volume / time available for the copy.
B25: Time to copy all data | C25: =IF(AND(AND(ISNUMBER(C13),C13>0),AND(ISNUMBER(C20),C20>0)),C13/C20,"Unknown") -> 100 | D25: Minutes | F25: Data volume / assumed bulk speed.
B26: Estimated offline interruption | C26: =IF(AND(AND(ISNUMBER(C25),C25>=0),AND(ISNUMBER(C18),C18>=0),AND(ISNUMBER(C19),C19>=1)),(C25+C18)*C19,"Unknown") -> 137.5 | D26: Minutes | F26: (Copy time + other cutover work) × planning factor.
B27: Requirement completeness | C27: =IF(AND(AND(ISNUMBER(C13),C13>0),AND(ISNUMBER(C14),C14>0),AND(ISNUMBER(C15),C15>=0),AND(ISNUMBER(C16),C16>=0),AND(ISNUMBER(C18),C18>=0),AND(ISNUMBER(C19),C19>=1),AND(ISNUMBER(C20),C20>0),OR(C12="Offline",C12="Online",C12="No preference")),"Complete","Unknown") -> Complete | F27: Missing or invalid values are not treated as zero.
B28: Screening result | C28: =IF(C27="Unknown","Unknown",IF(C23<=0,"Revise cutover plan",IF(C26<=C14,"Offline candidate","Evaluate online"))) -> Evaluate online | F28: If offline does not fit, assess online using the Advanced model.
B30: Read the result
B31: Offline candidate | F31: Offline fits the assumed speed. Measure that speed and verify rollback.
B32: Evaluate online | F32: Offline exceeds the budget at this speed. CDC has not yet been approved.
B33: Revise cutover plan | F33: The assumed other work leaves no time for a full copy.
B34: Unknown | F34: Complete the missing or invalid inputs before using the result.
B36: Network delay | C36: =IF(ISNUMBER(C16),C16,"Unknown") -> 40 | D36: Milliseconds | F36: Measure the proposed process across a network with this delay.
B37: Preferred approach | C37: =C12 -> No preference | F37: Compare this preference with the screening result.

Sheet Advanced
B2: Advanced migration model
B3: Common requirements link to Simple. Yellow cells are editable.
B4: Decision
B5: Offline overall | C5: =C64 -> Not feasible | F5: Overall includes capability, evidence, cutover and rollback checks.
B6: Online overall | C6: =D65 -> Unknown | F6: Unknown means more evidence is needed; it is not a pass.
B7: Next step | C7: =C66 -> Resolve unknown checks | F7: See failed or unknown checks below to identify the next action.
B10: Shared requirements from Simple
B12: Data to copy | C12: =IF(Simple!C13="","Unknown",Simple!C13) -> 1000 | D12: GB | F12: Edit the shared requirement on Simple.
B13: Cutover budget | C13: =IF(Simple!C14="","Unknown",Simple!C14) -> 30 | D13: Minutes | F13: Edit the shared requirement on Simple.
B14: Rollback budget | C14: =IF(Simple!C15="","Unknown",Simple!C15) -> 15 | D14: Minutes | F14: Edit the shared requirement on Simple.
B15: Network round-trip delay | C15: =IF(Simple!C16="","Unknown",Simple!C16) -> 40 | D15: Milliseconds | F15: Edit the shared requirement on Simple.
B16: Planning factor | C16: =IF(Simple!C19="","Unknown",Simple!C19) -> 1.25 | D16: Multiplier | F16: Edit the shared requirement on Simple.
B17: Preferred approach | C17: =IF(Simple!C12="","Unknown",Simple!C12) -> No preference | D17: Choice | F17: Edit the shared requirement on Simple.
B19: Enter migration measurements and capability evidence
B20: Measured bulk speed | C20: 10 | D20: GB/minute | F20: Example rate for reading, moving and loading existing data.
B21: Source change rate | C21: 0.5 | D21: GB/minute | F21: Change data generated each minute during representative busy periods.
B22: CDC processing capacity | C22: 2 | D22: GB/minute | F22: Complete capture, transfer and apply capacity for comparable changes.
B23: Remaining source changes | C23: 4 | D23: GB | F23: Complete unapplied backlog at write freeze, including uncaptured changes.
B24: Other offline cutover work | C24: 10 | D24: Minutes | F24: Work during the outage outside copying data.
B25: Other online cutover work | C25: 10 | D25: Minutes | F25: Work during the outage outside finishing remaining changes.
B26: Offline capabilities confirmed | C26: Unknown | D26: Choice | F26: Consistent copying, data coverage and application readiness verified.
B27: Online capabilities confirmed | C27: Unknown | D27: Choice | F27: Bulk load, CDC coverage, retention and application readiness verified.
B28: Performance evidence | C28: Assumed | D28: Choice | F28: Choose Measured only after representative tests support these rates.
B30: Rollback plan inputs | C30: Offline | D30: Online
B31: Target changes to restore | C31: 2 | D31: 2 | F31: GB. Count changes required by the permitted data-loss limit.
B32: Speed to restore those changes | C32: 1 | D32: 1 | F32: GB/minute. Not needed when the required restore volume is zero.
B33: Other rollback work | C33: 6 | D33: 6 | F33: Minutes. Stop target writes, validate the source and switch back.
B34: Recovery method confirmed | C34: Unknown | D34: Unknown | F34: Yes means a compatible, tested return-to-source procedure exists.
B35: Maximum allowed data loss | C35: 0 | D35: 0 | F35: Minutes of recent committed activity. Zero means no data loss.
B36: Expected data loss on return | C36: 0 | D36: 0 | F36: Minutes. Estimate from the recovery method, not its transfer rate.
B37: Required rollback coverage | C37: 120 | D37: 120 | F37: Minutes after cutover during which rollback must remain possible.
B38: Demonstrated rollback coverage | C38: 120 | D38: 120 | F38: Minutes supported by the tested recovery plan.
F39: Example values are illustrative. Leave unknown measurements blank.
B42: Migration calculations
B44: Initial full-copy time | C44: =IF(AND(AND(ISNUMBER(C12),C12>0),AND(ISNUMBER(C20),C20>0)),C12/C20,"Unknown") -> 100 | D44: Minutes | F44: The initial online copy also takes time, but precedes the final outage.
B45: Offline interruption | C45: =IF(AND(AND(ISNUMBER(C44),C44>=0),AND(ISNUMBER(C24),C24>=0),AND(ISNUMBER(C16),C16>=1)),(C44+C24)*C16,"Unknown") -> 137.5 | D45: Minutes | F45: (Full-copy time + other offline work) × planning factor.
B46: CDC spare capacity | C46: =IF(AND(AND(ISNUMBER(C22),C22>0),AND(ISNUMBER(C21),C21>=0)),C22-C21,"Unknown") -> 1.5 | D46: GB/minute | F46: CDC capacity - source change rate; must be greater than zero.
B47: Can CDC keep up? | C47: =IF(ISNUMBER(C46),IF(C46>0,"Pass","Not feasible"),"Unknown") -> Pass
B48: Time to finish remaining changes | C48: =IF(AND(AND(ISNUMBER(C23),C23>=0),AND(ISNUMBER(C22),C22>0)),C23/C22,"Unknown") -> 2 | D48: Minutes | F48: Remaining source changes / CDC capacity after source writes stop.
B49: Online interruption | C49: =IF(AND(AND(ISNUMBER(C48),C48>=0),AND(ISNUMBER(C25),C25>=0),AND(ISNUMBER(C16),C16>=1)),(C48+C25)*C16,"Unknown") -> 15 | D49: Minutes | F49: (Time for remaining changes + other online work) × planning factor.
...

Sheet Guide
B2: Using the migration models
B5: Start with Simple | C5: Enter shared requirements and an assumed complete bulk-copy speed.
B6: Read the screening result | C6: Offline candidate means it fits the assumptions; rollback still needs testing.
B7: Then use Advanced | C7: Enter measurements and confirm migration and recovery capabilities.
B8: Use separate recovery plans | C8: Offline and online may need different return-to-source procedures.
B9: Yellow cells | C9: Editable inputs. Unfilled cells represent missing evidence, not zero.
B10: Shared requirements | C10: Advanced links to Simple; change the shared values only on Simple.
B11: Prefilled examples | C11: From the accompanying OraMatt draft. They are not performance guarantees.
B12: Measured evidence | C12: Choose Measured only when tests represent the workload and network.
B13: Feasible | C13: All modeled requirements pass with confirmed capabilities and measurements.
B14: Not feasible | C14: At least one known required check fails.
B15: Unknown | C15: Required information or confirmation is still missing.
B16: Cutover | C16: Switching the application from the existing database to the new database.
... B32: Auther | C32: Matt DeMarco (oramatt / https://oramatt.com/ )
